Workbook
Name Slicer_Category: #N/A
Name Slicer_Month: #N/A
Name Slicer_Year: #N/A

Sheet Data
A1: Order Date | B1: Customer Name | C1: State | D1: Category | E1: Sub-Category | F1: Product Name | G1: Sales | H1: Quantity | I1: Profit | J1: Month | K1: Year
A2: 44199 | B2: Darren Powers | C2: Texas | D2: Office Supplies | E2: Paper | F2: Message Book, Wirebound, Four 5 1/2" X 4" Forms/Pg., 200 Dupl. Sets/Book | G2: 16.45 | H2: 2 | I2: 5.55 | J2: Jan | K2: 2021
A3: 44200 | B3: Phillina Ober | C3: Illinois | D3: Office Supplies | E3: Labels | F3: Avery 508 | G3: 11.78 | H3: 3 | I3: 4.27 | J3: Jan | K3: 2021
A4: 44200 | B4: Phillina Ober | C4: Illinois | D4: Office Supplies | E4: Storage | F4: SAFCO Boltless Steel Shelving | G4: 272.74 | H4: 3 | I4: -64.77 | J4: Jan | K4: 2021
A5: 44200 | B5: Phillina Ober | C5: Illinois | D5: Office Supplies | E5: Binders | F5: GBC Standard Plastic Binding Systems Combs | G5: 3.54 | H5: 2 | I5: -5.49 | J5: Jan | K5: 2021
A6: 44201 | B6: Mick Brown | C6: Pennsylvania | D6: Office Supplies | E6: Art | F6: Avery Hi-Liter EverBold Pen Style Fluorescent Highlighters, 4/Pack | G6: 19.54 | H6: 3 | I6: 4.88 | J6: Jan | K6: 2021
A7: 44202 | B7: Lycoris Saunders | C7: California | D7: Office Supplies | E7: Paper | F7: Xerox 225 | G7: 19.44 | H7: 3 | I7: 9.33 | J7: Jan | K7: 2021
A8: 44202 | B8: Jack O'Briant | C8: Georgia | D8: Office Supplies | E8: Art | F8: Dixon Prang Watercolor Pencils, 10-Color Set with Brush | G8: 12.78 | H8: 3 | I8: 5.24 | J8: Jan | K8: 2021
A9: 44202 | B9: Maria Etezadi | C9: Kentucky | D9: Furniture | E9: Chairs | F9: Global Deluxe High-Back Manager's Chair | G9: 2573.82 | H9: 9 | I9: 746.41 | J9: Jan | K9: 2021
A10: 44202 | B10: Maria Etezadi | C10: Kentucky | D10: Office Supplies | E10: Binders | F10: Ibico Hi-Tech Manual Binding System | G10: 609.98 | H10: 2 | I10: 274.49 | J10: Jan | K10: 2021
A11: 44202 | B11: Maria Etezadi | C11: Kentucky | D11: Office Supplies | E11: Art | F11: Rogers Handheld Barrel Pencil Sharpener | G11: 5.48 | H11: 2 | I11: 1.48 | J11: Jan | K11: 2021
A12: 44202 | B12: Maria Etezadi | C12: Kentucky | D12: Technology | E12: Phones | F12: GE 30524EE4 | G12: 391.98 | H12: 2 | I12: 113.67 | J12: Jan | K12: 2021
A13: 44202 | B13: Maria Etezadi | C13: Kentucky | D13: Technology | E13: Phones | F13: Wireless Extenders zBoost YX545 SOHO Signal Booster | G13: 755.96 | H13: 4 | I13: 204.11 | J13: Jan | K13: 2021
... A8315: 45535 | B8315: Maxwell Schwartz | C8315: California | D8315: Office Supplies | E8315: Storage | F8315: Space Solutions Commercial Steel Shelving | G8315: 193.95 | H8315: 3 | I8315: 9.7 | J8315: Aug | K8315: 2024

Sheet Detail1
A1: Details for Sum of Profit - Customer Name: Tamara Chand
A3: Order Date | B3: Customer Name | C3: State | D3: Category | E3: Sub-Category | F3: Product Name | G3: Sales | H3: Quantity | I3: Profit | J3: Month | K3: Year
A4: 45256 | B4: Tamara Chand | C4: Washington | D4: Office Supplies | E4: Binders | F4: Newell 3-Hole Punched Plastic Slotted Magazine Holders for Binders | G4: 7.31 | H4: 2 | I4: 2.56 | J4: Nov | K4: 2023
A5: 45201 | B5: Tamara Chand | C5: Indiana | D5: Office Supplies | E5: Art | F5: Stanley Bostitch Contemporary Electric Pencil Sharpeners | G5: 33.96 | H5: 2 | I5: 9.51 | J5: Oct | K5: 2023
A6: 45201 | B6: Tamara Chand | C6: Indiana | D6: Office Supplies | E6: Binders | F6: Acco Pressboard Covers with Storage Hooks, 14 7/8" x 11", Light Blue | G6: 34.37 | H6: 7 | I6: 16.84 | J6: Oct | K6: 2023
A7: 45201 | B7: Tamara Chand | C7: Indiana | D7: Office Supplies | E7: Binders | F7: Ibico Ibimaster 300 Manual Binding System | G7: 735.98 | H7: 2 | I7: 331.19 | J7: Oct | K7: 2023
A8: 45201 | B8: Tamara Chand | C8: Indiana | D8: Technology | E8: Copiers | F8: Canon imageCLASS 2200 Advanced Copier | G8: 17499.95 | H8: 5 | I8: 8399.98 | J8: Oct | K8: 2023
A9: 45201 | B9: Tamara Chand | C9: Indiana | D9: Office Supplies | E9: Storage | F9: Acco Perma 4000 Stacking Storage Drawers | G9: 32.48 | H9: 2 | I9: 4.87 | J9: Oct | K9: 2023
A10: 44824 | B10: Tamara Chand | C10: New York | D10: Office Supplies | E10: Binders | F10: Recycled Premium Regency Composition Covers | G10: 24.45 | H10: 2 | I10: 8.86 | J10: Sep | K10: 2022
A11: 44824 | B11: Tamara Chand | C11: New York | D11: Office Supplies | E11: Paper | F11: Xerox 1881 | G11: 61.4 | H11: 5 | I11: 28.86 | J11: Sep | K11: 2022
A12: 44557 | B12: Tamara Chand | C12: Alabama | D12: Technology | E12: Accessories | F12: Enermax Acrylux Wireless Keyboard | G12: 498 | H12: 5 | I12: 184.26 | J12: Dec | K12: 2021
A13: 44557 | B13: Tamara Chand | C13: Alabama | D13: Office Supplies | E13: Paper | F13: Xerox 1983 | G13: 23.92 | H13: 4 | I13: 11.72 | J13: Dec | K13: 2021
A14: 44507 | B14: Tamara Chand | C14: Texas | D14: Office Supplies | E14: Envelopes | F14: Staple envelope | G14: 74.35 | H14: 3 | I14: 26.95 | J14: Nov | K14: 2021
A15: 44507 | B15: Tamara Chand | C15: Texas | D15: Office Supplies | E15: Binders | F15: Satellite Sectional Post Binders | G15: 26.05 | H15: 3 | I15: -44.28 | J15: Nov | K15: 2021

Sheet PIVOT TABLE
A3: Total Sales | T3: Customer Count By Year | W3: Sales by State
A4: Sum of Sales | D4: Profit By Year | K4: Sales by Sub Category | N4: Category | O4: Sales | T4: Row Labels | U4: Count of Customer Name | W4: Row Labels | X4: Sum of Sales2 | Z4: State | AA4: Sales | AC4: Top 5 Customers Profit | AF4: Sales By Month
A5: 1928887.9 | D5: Sum of Profit2 | E5: Column Labels | K5: Row Labels | L5: Sum of Sales | N5: =K6 -> Phones | O5: =L6 -> 279464.42 | Q5: =Data!B1 -> Customer Name | R5: =Data!K1 -> Year | T5: 0 | U5: 1 | W5: Alabama | X5: 18299.32 | Z5: =W5 -> Alabama | AA5: =X5 -> 18299.32 | AC5: Row Labels | AD5: Sum of Profit | AF5: Row Labels | AG5: Sum of Sales
D6: Row Labels | E6: Furniture | F6: Office Supplies | G6: Technology | H6: Grand Total | K6: Phones | L6: 279464.42 | N6: =K7 -> Chairs | O6: =L7 -> 277058.98 | Q6: =Data!B2 -> Darren Powers | R6: =Data!K2 -> 2021 | T6: 2021 | U6: 595 | W6: Arizona | X6: 28978.85 | Z6: =W6 -> Arizona | AA6: =X6 -> 28978.85 | AC6: Tamara Chand | AD6: 8981.32 | AF6: Jan | AG6: 94924.87
A7: Total Profit | D7: 2021 | E7: 5469.77 | F7: 22593.4 | G7: 21492.95 | H7: 49556.12 | K7: Chairs | L7: 277058.98 | N7: =K8 -> Storage | O7: =L8 -> 190679.61 | Q7: =Data!B3 -> Phillina Ober | R7: =Data!K3 -> 2021 | T7: 2022 | U7: 573 | W7: Arkansas | X7: 9177.42 | Z7: =W7 -> Arkansas | AA7: =X7 -> 9177.42 | AC7: Raymond Buch | AD7: 6939.17 | AF7: Feb | AG7: 59640.16
A8: Sum of Profit | D8: 2022 | E8: 3015.17 | F8: 25099.55 | G8: 33503.97 | H8: 61618.69 | K8: Storage | L8: 190679.61 | N8: =K9 -> Binders | O8: =L9 -> 169089.73 | Q8: =Data!B6 -> Mick Brown | R8: =Data!K6 -> 2021 | T8: 2023 | U8: 638 | W8: California | X8: 390145.54 | Z8: =W8 -> California | AA8: =X8 -> 390145.54 | AC8: Sanjit Chand | AD8: 5757.42 | AF8: Mar | AG8: 205005.51
A9: 247961.07 | D9: 2023 | E9: 6959.93 | F9: 35052.91 | G9: 39774.1 | H9: 81786.94 | K9: Binders | L9: 169089.73 | N9: =K10 -> Tables | O9: =L10 -> 167672.76 | Q9: =Data!B7 -> Lycoris Saunders | R9: =Data!K7 -> 2021 | T9: 2024 | U9: 513 | W9: Colorado | X9: 27113.92 | Z9: =W9 -> Colorado | AA9: =X9 -> 27113.92 | AC9: Adrian Barton | AD9: 5202.84 | AF9: Apr | AG9: 137480.79
D10: 2024 | E10: 2443.8 | F10: 25464.81 | G10: 27090.71 | H10: 54999.32 | K10: Tables | L10: 167672.76 | N10: =K11 -> Machines | O10: =L11 -> 166777.78 | Q10: =Data!B8 -> Jack O'Briant | R10: =Data!K8 -> 2021 | T10: Grand Total | U10: 2320 | W10: Connecticut | X10: 11471.42 | Z10: =W10 -> Connecticut | AA10: =X10 -> 11471.42 | AC10: Martinez | AD10: 3883.09 | AF10: May | AG10: 155028.83
D11: Grand Total | E11: 17888.67 | F11: 108210.67 | G11: 121861.73 | H11: 247961.07 | K11: Machines | L11: 166777.78 | N11: =K12 -> Accessories | O11: =L12 -> 139241.71 | Q11: =Data!B9 -> Maria Etezadi | R11: =Data!K9 -> 2021 | W11: Delaware | X11: 16302.24 | Z11: =W11 -> Delaware | AA11: =X11 -> 16302.24 | AC11: Grand Total | AD11: 30763.84 | AF11: Jun | AG11: 152718.72
A12: {=A4:A5} -> Sum of Sales | K12: Accessories | L12: 139241.71 | N12: =K13 -> Copiers | O12: =L13 -> 118968.24 | Q12: =Data!B16 -> Vivek Sundaresam | R12: =Data!K16 -> 2021 | W12: District of Columbia | X12: 2865.02 | Z12: =W12 -> District of Columbia | AA12: =X12 -> 2865.02 | AF12: Jul | AG12: 147238.11
A13: 1928887.9 | K13: Copiers | L13: 118968.24 | N13: =K14 -> Bookcases | O13: =L14 -> 101387.67 | Q13: =Data!B18 -> Melanie Seite | R13: =Data!K18 -> 2021 | W13: Florida | X13: 79303.61 | Z13: =W13 -> Florida | AA13: =X13 -> 79303.61 | AF13: Aug | AG13: 159043.99
K14: Bookcases | L14: 101387.67 | N14: =K15 -> Appliances | O14: =L15 -> 87846.1 | Q14: =Data!B20 -> Anthony Jacobs | R14: =Data!K20 -> 2021 | W14: Georgia | X14: 46346.2 | Z14: =W14 -> Georgia | AA14: =X14 -> 46346.2 | AF14: Sep | AG14: 219783.3
A15: {=A8:A9} -> Sum of Profit | K15: Appliances | L15: 87846.1 | N15: =K16 -> Furnishings | O15: =L16 -> 76222.69 | Q15: =Data!B22 -> Seth Vernon | R15: =Data!K22 -> 2021 | W15: Idaho | X15: 3963.47 | Z15: =W15 -> Idaho | AA15: =X15 -> 3963.47 | AF15: Oct | AG15: 122546.07
A16: 247961.07 | K16: Furnishings | L16: 76222.69 | N16: =K17 -> Paper | O16: =L17 -> 64529.99 | Q16: =Data!B23 -> Chris Selesnick | R16: =Data!K23 -> 2021 | W16: Illinois | X16: 68565.03 | Z16: =W16 -> Illinois | AA16: =X16 -> 68565.03 | AF16: Nov | AG16: 234013.28
K17: Paper | L17: 64529.99 | N17: =K18 -> Supplies | O17: =L18 -> 38554.81 | Q17: =Data!B28 -> Natalie DeCherney | R17: =Data!K28 -> 2021 | W17: Indiana | X17: 47809.55 | Z17: =W17 -> Indiana | AA17: =X17 -> 47809.55 | AF17: Dec | AG17: 241464.23
K18: Supplies | L18: 38554.81 | N18: =K19 -> Art | O18: =L19 -> 23145.5 | Q18: =Data!B29 -> Brian Dahlen | R18: =Data!K29 -> 2021 | W18: Iowa | X18: 4476.41 | Z18: =W18 -> Iowa | AA18: =X18 -> 4476.41 | AF18: Grand Total | AG18: 1928887.9
K19: Art | L19: 23145.5 | N19: =K20 -> Envelopes | O19: =L20 -> 14717.39 | Q19: =Data!B32 -> Michael Moore | R19: =Data!K32 -> 2021 | W19: Kansas | X19: 2835 | Z19: =W19 -> Kansas | AA19: =X19 -> 2835
K20: Envelopes | L20: 14717.39 | N20: =K21 -> Labels | O20: =L21 -> 11045.55 | Q20: =Data!B34 -> Brendan Sweed | R20: =Data!K34 -> 2021 | W20: Kentucky | X20: 23650.59 | Z20: =W20 -> Kentucky | AA20: =X20 -> 23650.59
K21: Labels | L21: 11045.55 | N21: =K22 -> Fasteners | O21: =L22 -> 2484.93 | Q21: =Data!B35 -> Erica Hackney | R21: =Data!K35 -> 2021 | W21: Louisiana | X21: 5297.05 | Z21: =W21 -> Louisiana | AA21: =X21 -> 5297.05
K22: Fasteners | L22: 2484.93 | N22: =K23 -> Grand Total | O22: =L23 -> 1928887.9 | Q22: =Data!B36 -> Delfina Latchford | R22: =Data!K36 -> 2021 | W22: Maine | X22: 1270.53 | Z22: =W22 -> Maine | AA22: =X22 -> 1270.53
K23: Grand Total | L23: 1928887.9 | Q23: =Data!B40 -> David Wiener | R23: =Data!K40 -> 2021 | W23: Maryland | X23: 18580.9 | Z23: =W23 -> Maryland | AA23: =X23 -> 18580.9
Q24: =Data!B41 -> Toby Swindell | R24: =Data!K41 -> 2021 | W24: Massachusetts | X24: 23040.06 | Z24: =W24 -> Massachusetts | AA24: =X24 -> 23040.06
Q25: =Data!B45 -> Hunter Lopez | R25: =Data!K45 -> 2021 | W25: Michigan | X25: 66559.09 | Z25: =W25 -> Michigan | AA25: =X25 -> 66559.09
Q26: =Data!B51 -> Mark Van Huff | R26: =Data!K51 -> 2021 | W26: Minnesota | X26: 25069.12 | Z26: =W26 -> Minnesota | AA26: =X26 -> 25069.12
Q27: =Data!B53 -> Xylona Preis | R27: =Data!K53 -> 2021 | W27: Mississippi | X27: 9528.44 | Z27: =W27 -> Mississippi | AA27: =X27 -> 9528.44
Q28: =Data!B61 -> Muhammed MacIntyre | R28: =Data!K61 -> 2021 | W28: Missouri | X28: 18470.04 | Z28: =W28 -> Missouri | AA28: =X28 -> 18470.04
Q29: =Data!B62 -> Tom Boeckenhauer | R29: =Data!K62 -> 2021 | W29: Montana | X29: 5549.45 | Z29: =W29 -> Montana | AA29: =X29 -> 5549.45
Q30: =Data!B63 -> Ionia McGrath | R30: =Data!K63 -> 2021 | W30: Nebraska | X30: 4063.06 | Z30: =W30 -> Nebraska | AA30: =X30 -> 4063.06
Q31: =Data!B64 -> Speros Goranitis | R31: =Data!K64 -> 2021 | W31: Nevada | X31: 15059.5 | Z31: =W31 -> Nevada | AA31: =X31 -> 15059.5
Q32: =Data!B65 -> Shirley Daniels | R32: =Data!K65 -> 2021 | W32: New Hampshire | X32: 7210.3 | Z32: =W32 -> New Hampshire | AA32: =X32 -> 7210.3
Q33: =Data!B72 -> Carol Adams | R33: =Data!K72 -> 2021 | W33: New Jersey | X33: 29833.01 | Z33: =W33 -> New Jersey | AA33: =X33 -> 29833.01
Q34: =Data!B74 -> Ed Jacobs | R34: =Data!K74 -> 2021 | W34: New Mexico | X34: 3519.2 | Z34: =W34 -> New Mexico | AA34: =X34 -> 3519.2
Q35: =Data!B77 -> Jasper Cacioppo | R35: =Data!K77 -> 2021 | W35: New York | X35: 246517.74 | Z35: =W35 -> New York | AA35: =X35 -> 246517.74
Q36: =Data!B78 -> Mike Vittorini | R36: =Data!K78 -> 2021 | W36: North Carolina | X36: 37450.27 | Z36: =W36 -> North Carolina | AA36: =X36 -> 37450.27
Q37: =Data!B80 -> Liz Carlisle | R37: =Data!K80 -> 2021 | W37: North Dakota | X37: 891.53 | Z37: =W37 -> North Dakota | AA37: =X37 -> 891.53
Q38: =Data!B81 -> Bradley Drucker | R38: =Data!K81 -> 2021 | W38: Ohio | X38: 66407.17 | Z38: =W38 -> Ohio | AA38: =X38 -> 66407.17
Q39: =Data!B82 -> Cynthia Delaney | R39: =Data!K82 -> 2021 | W39: Oklahoma | X39: 17021.93 | Z39: =W39 -> Oklahoma | AA39: =X39 -> 17021.93
Q40: =Data!B83 -> Eric Barreto | R40: =Data!K83 -> 2021 | W40: Oregon | X40: 15189.98 | Z40: =W40 -> Oregon | AA40: =X40 -> 15189.98
Q41: =Data!B87 -> Deborah Brumfield | R41: =Data!K87 -> 2021 | W41: Pennsylvania | X41: 95494.86 | Z41: =W41 -> Pennsylvania | AA41: =X41 -> 95494.86
Q42: =Data!B89 -> Mark Haberlin | R42: =Data!K89 -> 2021 | W42: Rhode Island | X42: 19695.42 | Z42: =W42 -> Rhode Island | AA42: =X42 -> 19695.42
...

Sheet Dashboard
